<mujoco>
    <body name="base" pos="0 0 0">
        <!-- robot view -->
        <camera mode="fixed" name="robotview" pos="1.0 0 0.4" quat="0.653 0.271 0.271 0.653"/>
        <inertial diaginertia="0 0 0" mass="0" pos="0 0 0"/>
        <!-- mount attached here -->
        <body name="link0" pos="0 0 0">
            <inertial pos="0 0 0.05" mass="4" diaginertia="0.4 0.4 0.4" />
            <geom type="mesh" contype="0" conaffinity="0" group="1" mesh="link0_vis" name="link0_visual" rgba="1 1 1 0" />
            <geom type="mesh" group="0" mesh="link0" name="link0_collision" rgba="1 1 1 1"/>
            <body name="link1" pos="0 0 0.333">
                <inertial pos="0 0 -0.07" mass="3" diaginertia="0.3 0.3 0.3" />
                <joint name="panda0_joint1" pos="0 0 0" axis="0 0 1" limited="true" range="-2.8973 2.8973" damping="0.1"/>
                <geom type="mesh" contype="0" conaffinity="0" group="1" mesh="link1_vis" name="link1_visual" rgba="1 1 1 0" />
                <geom type="mesh" group="0" mesh="link1" name="link1_collision" rgba="1 1 1 1"/>
                <body name="link2" pos="0 0 0" quat="0.707107 -0.707107 0 0">
                    <inertial pos="0 -0.1 0" mass="3" diaginertia="0.3 0.3 0.3" />
                    <joint name="panda0_joint2" pos="0 0 0" axis="0 0 1" limited="true" range="-1.7628 1.7628" damping="0.1"/>
                    <geom type="mesh" contype="0" conaffinity="0" group="1" mesh="link2_vis" name="link2_visual" rgba="1 1 1 0" />
                    <geom type="mesh" group="0" mesh="link2" name="link2_collision" rgba="1 1 1 1"/>
                    <body name="link3" pos="0 -0.316 0" quat="0.707107 0.707107 0 0">
                        <inertial pos="0.04 0 -0.05" mass="2" diaginertia="0.2 0.2 0.2" />
                        <joint name="panda0_joint3" pos="0 0 0" axis="0 0 1" limited="true" range="-2.8973 2.8973" damping="0.1"/>
                        <geom type="mesh" contype="0" conaffinity="0" group="1" mesh="link3_vis" name="link3_visual" rgba="1 1 1 0" />
                        <geom type="mesh" group="0" mesh="link3" name="link3_collision" rgba="1 1 1 1"/>
                        <body name="link4" pos="0.0825 0 0" quat="0.707107 0.707107 0 0">
                            <inertial pos="-0.04 0.05 0" mass="2" diaginertia="0.2 0.2 0.2" />
                            <joint name="panda0_joint4" pos="0 0 0" axis="0 0 1" limited="true" range="-3.0718 -0.0698" damping="0.1"/>
                            <geom type="mesh" contype="0" conaffinity="0" group="1" mesh="link4_vis" name="link4_visual" rgba="1 1 1 0" />
                            <geom type="mesh" group="0" mesh="link4" name="link4_collision" rgba="1 1 1 1"/>
                            <body name="link5" pos="-0.0825 0.384 0" quat="0.707107 -0.707107 0 0">
                                <inertial pos="0 0 -0.15" mass="2" diaginertia="0.2 0.2 0.2" />
                                <joint name="panda0_joint5" pos="0 0 0" axis="0 0 1" limited="true" range="-2.8973 2.8973" damping="0.1"/>
                                <geom type="mesh" contype="0" conaffinity="0" group="1" mesh="link5_vis" name="link5_visual" rgba="1 1 1 0" />
                                <geom type="mesh" group="0" mesh="link5" name="link5_collision" rgba="1 1 1 1"/>
                                <body name="link6" pos="0 0 0" quat="0.707107 0.707107 0 0">
                                    <inertial pos="0.06 0 0" mass="1.5" diaginertia="0.1 0.1 0.1" />
                                    <joint name="panda0_joint6" pos="0 0 0" axis="0 0 1" limited="true" range="-0.0175 3.7525" damping="0.01"/>
                                    <geom type="mesh" contype="0" conaffinity="0" group="1" mesh="link6_vis" name="link6_visual" rgba="1 1 1 0" />
                                    <geom type="mesh" group="0" mesh="link6" name="link6_collision" rgba="1 1 1 1"/>
                                    <body name="link7" pos="0.088 0 0" quat="0.707107 0.707107 0 0">
                                        <inertial pos="0 0 0.08" mass="0.5" diaginertia="0.05 0.05 0.05" />
                                        <joint name="panda0_joint7" pos="0 0 0" axis="0 0 1" limited="true" range="-2.8973 2.8973" damping="0.01"/>
                                        <geom type="mesh" contype="0" conaffinity="0" group="1" mesh="link7_vis" name="link7_visual" rgba="1. 1. 1. 0." />
                                        <geom type="mesh" group="0" mesh="link7" name="link7_collision" rgba="1 1 1 1"/>
                                        <!-- rotate 135deg to align physically to the tool-->
                                        <body name="right_hand" pos="0 0 0.1065" quat="0.924 0 0 -0.383">
                                            <inertial pos="0 0 0" mass="0.5" diaginertia="0.05 0.05 0.05" />
                                            <!-- This camera points out from the eef. -->
                                            <camera mode="fixed" name="eye_in_hand" pos="0.05 0 0" quat="0 0.707108 0.707108 0" fovy="75"/>
                                            <!-- to add gripper -->
                                            <include file="gripper.xml"/>
                                        </body>
                                    </body>
                                </body>
                            </body>
                        </body>
                    </body>
                </body>
            </body>
        </body>
    </body>
</mujoco>
