<?xml version="1.0" encoding="utf-8"?>
<mujoco>
	<compiler angle="radian" coordinate="local" meshdir="" texturedir="../textures"></compiler>
	<option timestep="0.002">
		<flag warmstart="enable"/>
	</option>
	<size nuser_actuator="5"/>

	<include file="franka_shared.xml"></include>

	<worldbody>

		<geom name="floor0" pos="0.8 0.75 0" size="0.85 0.70 1" type="plane" condim="3" material="floor_mat"></geom>
		<body name="floor0" pos="0.8 0.75 0">
			<site name="target0" pos="0 0 0.5" size="0.02 0.02 0.02" rgba="1 0 0 1" type="sphere"></site>
		</body>
<!--		<body name="external_camera_1" pos="3.5 0.75 1.6">-->
<!--			<camera euler="0 1.1 1.57" fovy="43.3" name="ex_camera_1" pos="0 0 0"></camera>-->
<!--		</body>-->

		<body name="panda_table" pos="0.5 0.75 0.18">
			<geom size="0.5 0.35 0.18" pos="0.05 0 0" type="box" mass="3000" material="table_mat"/>
			<body name="panda_base" pos="0.44 0 0.18">
				<include file="franka_robot.xml"></include>
			</body>
		</body>
		<body mocap="true" name="panda0:mocap" pos="0 0 0" euler="3.14159 1.5708 0">
			<geom conaffinity="0" contype="0" pos="0 0 0" rgba="0 0.5 0 0.7" size="0.005 0.005 0.005" type="box"></geom>
			<geom conaffinity="0" contype="0" pos="0 0 0" rgba="0 0.5 0 0.1" size="1 0.005 0.005" type="box"></geom>
			<geom conaffinity="0" contype="0" pos="0 0 0" rgba="0 0.5 0 0.1" size="0.005 1 0.001" type="box"></geom>
			<geom conaffinity="0" contype="0" pos="0 0 0" rgba="0 0.5 0 0.1" size="0.005 0.005 1" type="box"></geom>
		</body>
		<body pos="1.3 0.75 0.2" name="table0">
			<geom size="0.3 0.35 0.2" pos="0.05 0 0" type="box" mass="2000" material="table_mat"></geom>
			<site name="target_center" pos="-0.10 -0.19 0.2" size="0.02 0.02 0.02" rgba="0 0 1 1" type="sphere"></site>
			<site name="init_center" pos="-0.10 0.1 0.2" size="0.02 0.02 0.02" rgba="0 0 1 1" type="sphere"></site>
			<site name="init_1" pos="-1.875 0.45 0.2" size="0.02 0.02 0.02" rgba="0 1 0 0.1" type="sphere"></site>
			<site name="init_2" pos="-1.25 0.45 0.2" size="0.02 0.02 0.02" rgba="0 1 0 0.1" type="sphere"></site>
			<site name="init_3" pos="-0.625 0.45 0.2" size="0.02 0.02 0.02" rgba="0 1 0 0.1" type="sphere"></site>
			<site name="init_4" pos="0 0.45 0.2" size="0.02 0.02 0.02" rgba="0 1 0 0.1" type="sphere"></site>
			<site name="mark1" pos="0.625 0.45 0.2" size="0.02 0.02 0.02" rgba="0 0 1 0.1" type="sphere"></site>
			<site name="mark2" pos="1.25 0.45 0.2" size="0.02 0.02 0.02" rgba="0 0 1 0.1" type="sphere"></site>
			<site name="mark3" pos="1.875 0.45 0.2" size="0.02 0.02 0.02" rgba="0 0 1 0.1" type="sphere"></site>
			<site name="mark4" pos="-1.875 -0.45 0.2" size="0.02 0.02 0.02" rgba="0 0 1 0.1" type="sphere"></site>
			<site name="mark5" pos="-0.10 0.1 0.2" size="0.04 0.04 0.04" rgba="0 0 1 0.1" type="sphere"></site>
		</body>

		<body pos="1.5 0.60 0.435" name="dyn_obstacle:site">
			<site name="dyn_obstacle:site" size="0.15 0.03 0.035" rgba="1 0 0 0.05" type="box"></site>
		</body>

		<body pos="1.5 0.60 0.435" name="dyn_obstacle">
			<!--limited="true" range="-.05 .05"  damping='0.01' armature='0' frictionloss='0.1'-->
			<geom name="dyn_obstacle:geom" pos="0 0 0" size="0.03 0.03 0.03" type="box" rgba="0 0 1 1" mass="2000" material="table_mat"></geom>
			<joint name="dyn_obstacle:joint" type="slide" axis="1 0 0" limited="true" damping="0.01" range="-.25 .25" margin="0.03"></joint>
		</body>

		<body pos="1.5 0.80 0.435" name="dyn_obstacle2:site">
			<site name="dyn_obstacle2:site" size="0.15 0.03 0.035" rgba="1 0 0 0.05" type="box"></site>
		</body>

		<body pos="1.5 0.80 0.435" name="dyn_obstacle2">
			<!--limited="true" range="-.05 .05"  damping='0.01' armature='0' frictionloss='0.1'-->
			<geom name="dyn_obstacle2:geom" pos="0 0 0" size="0.03 0.03 0.03" type="box" rgba="0 0 1 1" mass="2000" material="table_mat"></geom>
			<joint name="dyn_obstacle2:joint" type="slide" axis="1 0 0" limited="true" damping="0.01" range="-.25 .25" margin="0.03"></joint>
		</body>

		<body pos="1.3 0.75 0.43" name="space0">
			<site name="spacesite" pos="0.05 0 0" size="0.3 0.35 0.03" rgba="0 0 1 0.05" type="box"></site>
			<geom name="obstacle_1" pos="-0.1 0 0" size="0.11 0.02 0.03" type="box" mass="2000" material="table_mat" rgba="0 0 1 1"></geom>
			<geom name="obstacle_2" pos="-0.23 0 0" size="0.02 0.35 0.03" type="box" mass="2000" material="table_mat" rgba="0 0 1 1"></geom>
			<geom name="obstacle_3" pos="0.03 0 0" size="0.02 0.2 0.03" type="box" mass="2000" material="table_mat" rgba="0 0 1 1"></geom>
		</body>

		<body name="object0" pos="0.025 0.025 0.025">
			<joint name="object0:joint" type="free" damping="0.01"></joint>
			<geom size="0.025 0.025 0.025" type="box" condim="3" name="object0" material="block_mat" mass="2"></geom>
			<site name="object0" pos="0 0 0" size="0.02 0.02 0.02" rgba="1 0 0 1" type="sphere"></site>
		</body>

		<light directional="true" ambient="0.2 0.2 0.2" diffuse="0.8 0.8 0.8" specular="0.3 0.3 0.3" castshadow="false" pos="0 0 4" dir="0 0 -1" name="light0"></light>
	</worldbody>
</mujoco>
