<?xml version="1.0" encoding="utf-8"?>
<mujoco>
	<compiler angle="radian" coordinate="local" meshdir="" texturedir="../textures"></compiler>
	<option timestep="0.002">
		<flag warmstart="enable"/>
	</option>
	<size nuser_actuator="5"/>

	<include file="franka_shared.xml"></include>

    <worldbody>
        <geom name="floor0" pos="0.8 0.75 0" size="0.85 0.70 1" type="plane" condim="3" material="floor_mat"></geom>
		<body name="floor0" pos="0.8 0.75 0">
			<site name="target0" pos="0 0 0.5" size="0.02 0.02 0.02" rgba="1 0 0 1" type="sphere"></site>
		</body>
        <body name="panda_table" pos="0.5 0.75 0.2">
			<geom size="0.4 0.35 0.2" pos="0.05 0 0" type="box" mass="3000" material="table_mat"/>
			<body name="panda_base" pos="0.3 0 0.2">
				<include file="franka_robot.xml"></include>
			</body>
		</body>
        <body mocap="true" name="panda0:mocap" pos="0 0 0" euler="3.14159 1.5708 0">
			<geom conaffinity="0" contype="0" pos="0 0 0" rgba="0 0.5 0 0.7" size="0.005 0.005 0.005" type="box"></geom>
			<geom conaffinity="0" contype="0" pos="0 0 0" rgba="0 0.5 0 0.1" size="1 0.005 0.005" type="box"></geom>
			<geom conaffinity="0" contype="0" pos="0 0 0" rgba="0 0.5 0 0.1" size="0.005 1 0.001" type="box"></geom>
			<geom conaffinity="0" contype="0" pos="0 0 0" rgba="0 0.5 0 0.1" size="0.005 0.005 1" type="box"></geom>
		</body>
        <body pos="1.3 0.75 0.2" name="table0">
			<geom size="0.25 0.45 0.2" type="box" mass="2000" material="table_mat"></geom>
			<site name="target_center" pos="0 -0.3 0.2" size="0.01 0.01 0.01" rgba="0 0 1 0.5" type="sphere"></site>
			<site name="init_center" pos="0 0.3 0.2" size="0.01 0.01 0.01" rgba="0 0 1 0.5" type="sphere"></site>
			<site name="init_1" pos="-1.875 0.45 0.2" size="0.01 0.01 0.01" rgba="0 1 0 0.1" type="sphere"></site>
			<site name="init_2" pos="-1.25 0.45 0.2" size="0.01 0.01 0.01" rgba="0 1 0 0.1" type="sphere"></site>
			<site name="init_3" pos="-0.625 0.45 0.2" size="0.01 0.01 0.01" rgba="0 1 0 0.1" type="sphere"></site>
			<site name="init_4" pos="0 0.45 0.2" size="0.01 0.01 0.01" rgba="0 1 0 0.1" type="sphere"></site>
			<site name="mark1" pos="0.625 0.45 0.2" size="0.01 0.01 0.01" rgba="0 0 1 0.1" type="sphere"></site>
			<site name="mark2" pos="1.25 0.45 0.2" size="0.01 0.01 0.01" rgba="0 0 1 0.1" type="sphere"></site>
			<site name="mark3" pos="1.875 0.45 0.2" size="0.01 0.01 0.01" rgba="0 0 1 0.1" type="sphere"></site>
			<site name="mark4" pos="-1.875 -0.45 0.2" size="0.01 0.01 0.01" rgba="0 0 1 0.1" type="sphere"></site>
		</body>

		<body pos="1.3 0.75 0.6" name="space0">
			<site name="spacesite" size="0.25 0.35 0.2" rgba="0 0 1 0.05" type="box"></site>
		</body>

		<body pos="1.3 0.85 0.41" name="obstacle:site">
			<site name="obstacle:site" size="0.115 0.017 0.01" rgba="1 0 0 0.05" type="box"></site>
		</body>

		<body pos="1.3 0.65 0.41" name="obstacle2:site">
			<site name="obstacle2:site" size="0.115 0.017 0.01" rgba="1 0 0 0.05" type="box"></site>
		</body>

		<body pos="1.3 0.85 0.411" name="obstacle">
			<!--limited="true" range="-.05 .05"  damping='0.01' armature='0' frictionloss='0.1'-->
<!--			<site name="o" size="0.01 0.01 0.01" rgba="1 0 0 0.05" type="box"></site>-->
			<geom name="obstacle:geom" pos="0 0 0" size="0.015 0.017 0.01" type="box" rgba="0 0 1 1" mass="2000" material="table_mat"></geom>
			<joint name="obstacle:joint" type="slide" axis="1 0 0" limited="true" damping="0.01" range="-.1 .1" margin="0.001"></joint>
		</body>

		<body pos="1.3 0.65 0.411" name="obstacle2">
			<!--limited="true" range="-.05 .05"  damping='0.01' armature='0' frictionloss='0.1'-->
			<geom name="obstacle2:geom" pos="0 0 0" size="0.015 0.017 0.01" type="box" rgba="0 0 1 1" mass="2000" material="table_mat"></geom>
			<joint name="obstacle2:joint" type="slide" axis="1 0 0" limited="true" damping="0.01" range="-.1 .1" margin="0.001"></joint>
		</body>

		<body name="object0" pos="0.025 0.025 0.025">
			<joint name="object0:joint" type="free" damping="0.01"></joint>
			<geom size="0.015 0.015 0.015" type="box" condim="3" name="object0" material="block_mat" mass="2"></geom>
			<site name="object0" pos="0 0 0" size="0.01 0.01 0.01" rgba="1 0 0 1" type="sphere"></site>
		</body>

		<light directional="true" ambient="0.2 0.2 0.2" diffuse="0.8 0.8 0.8" specular="0.3 0.3 0.3" castshadow="false" pos="0 0 4" dir="0 0 -1" name="light0"></light>
    </worldbody>
</mujoco>
